Workbook

Sheet SITUACION COMERCIAL
A4: Actualización30/08/2024
A5: VENTAS | B5: =COUNTIF($A$12:$A$77,"RESERVADO") | E5: CUADRO MAESTRO DE SITUACIÓN (Actualización precios 11/06/2024)
A6: % s/unid.: | B6: =+$B$5/66 | C6: % S/importe.: | D6: =+#REF!/#REF!
A8: ESTADO | E8: INMUEBLES | N8: SUPERFICIES VIVIENDA (m2) | S8: PRECIOS | V8: FORMA DE PAGO ESTANDAR (IVA inlcuido) | AB8: DATOS CONTACTO COMPRADORES | AM8: INVESTICACION
E9: Nº Orden | F9: VIVIENDA | J9: ANEXOS | N9: Sup. Útil vivienda | O9: Sup. Útil terraza (50%) | P9: Sup.út Vvda. pp.terraz cubierta | Q9: Sup. Construida propia | R9: sup. patio/terraza desubieta | S9: Neto | T9: IVA | U9: TOTAL | V9: Reserva | W9: Compraventa | X9: Durante obra(20 pagos) | Y9: A llaves | Z9: Hipoteca contrato | AA9: Finca Registral
A10: Reservas: | B10: Fecha Reserva | C10: Fecha compravent. | F10: PORTAL | G10: PLANTA | H10: LETRA | I10: Nº Dorm. | J10: Garaje | K10: Trastero | L10: G. Adicional | M10: Tr. Adicional | AB10: TITULAR 1 | AE10: MAIL 1 | AF10: TITULAR 2 | AI10: MAIL 2 | AJ10: Situacion familiar | AK10: Dirección Contrato | AM10: cargas familiares | AN10: EDAD | AO10: Profecsión | AP10: €/mes | AQ10: EDAD | AR10: Profesión | AS10: €/mes | AT10: Hipoteca | AU10: Vende | AV10: Motivo compra | AX10: Procede
A12: BLOQUEADO | E12: 1 | F12: 1 | G12: BAJA | H12: A | I12: 4 | J12: 62 | K12: 56 | L12: . | M12: . | N12: 109.9 | O12: 9.52 | P12: 119.42 | Q12: 139.96 | R12: 25.81 | S12: 310000 | T12: 31000 | U12: 341000 | V12: 0 | W12: 0 | X12: 0 | Y12: 93000 | Z12: 248000 | AA12: 49350 | AM12: si | AN12: 34 | AO12: Ing. Informatico | AQ12: 41 | AR12: Direct. Escuela Infantil | AX12: Pardaleras | BB12: =IF(A12="RESERVADO",S12,"LIBRE")
A13: RESERVADO | B13: 44785 | C13: 45383 | E13: 2 | F13: 1 | G13: BAJA | H13: B | I13: 3 | J13: 57 | K13: 50 | L13: . | M13: . | N13: 90.04 | O13: 3.17 | P13: 93.21 | Q13: 107.77 | R13: 33.92 | S13: 234900 | T13: 23490 | U13: 258390 | V13: 12000 | W13: 20000 | X13: 19678 | Y13: 18792 | Z13: 187920 | AA13: =AA12+2 | AB13: MANUEL PEÑA GRAGERA | AE13: manuel.pgragera@gmail.com | AF13: JUAN FRANCISCO CERRATO MIRA | AI13: jfra_0099@hotmail.com | AJ13: soltero | AK13: C/. Eugenio Garcia Estop 16, 4ºD de Badajoz | AM13: no | AN13: 31 | AO13: Medico | AP13: 3000 | AQ13: 33 | AR13: Maestro | AS13: 2300 | AT13: 0.8 | AU13: No | AV13: 1ª vivienda | AX13: Ronda Norte | BB13: =IF(A13="RESERVADO",S13,"LIBRE") | BC13: ES57 0128 0060 5101 0005 4931
A14: RESERVADO | B14: 027/05/2023 | C14: 45534 | E14: 3 | F14: 1 | G14: BAJA | H14: C | I14: 2 | J14: NO | K14: 49 | L14: . | N14: 73.05 | O14: 3.3 | P14: 76.35 | Q14: 89.43 | R14: 0 | S14: 153000 | T14: 15300 | U14: 168300 | V14: 4950 | W14: 13563 | X14: 6732 | Y14: 20655 | Z14: 122400 | AA14: =AA13+2 | AB14: ISABEL PEREZ CORRALES | AE14: isabelperez57@hotmail.com | AK14: C/. Clavellinas 25, 1ºC de Badajoz | AM14: no | AN14: 63 | AO14: Funcionario | AP14: 1500 | AT14: 0 | AU14: no | AV14: Reposicion | AX14: Ciudad Jardin | BB14: =IF(A14="RESERVADO",S14,"LIBRE") | BC14: ES36 0182 0386 5702 0800 0441
A15: RESERVADO | B15: 45336 | C15: 45392 | E15: 4 | F15: 1 | G15: BAJA | H15: D | I15: 2 | J15: 40 | K15: 60 | L15: . | M15: . | N15: 70.72 | O15: 0 | P15: 70.72 | Q15: 85.24 | R15: 15.23 | S15: 178000 | T15: 17800 | U15: 195800 | V15: 5874 | W15: 19580 | X15: 5874 | Y15: 22072 | Z15: 142400 | AA15: =AA14+2 | AB15: ISIDORA ROMERO MARTIN | AE15: isiromeromartin@hotmail.com | AF15: ….............. | AK15: C/. Ramón y Cajal 15, Monterrubio de la Serena (Badajoz) | AN15: 52 | BB15: =IF(A15="RESERVADO",S15,"LIBRE") | BC15: ES70 2103 7308 9100 1002 6799
A16: RESERVADO | C16: 45842 | E16: 5 | F16: 1 | G16: BAJA | H16: E | I16: 2 | J16: 42 | K16: 18 | L16: . | M16: . | N16: 67.94 | O16: 0 | P16: 67.94 | Q16: 79.14 | R16: 29.89 | S16: 215000 | T16: 21500 | U16: 236500 | V16: 0 | W16: 28380 | X16: 7095 | Y16: 29025 | Z16: 172000 | AA16: =AA15+2 | AB16: JOKIN MIRAGAYA FERNANDEZ | AE16: jokin.miragaya@gmail.com | AF16: MARIA FERNANDEZ ROMERO | AJ16: casados | AK16: C/. GRPO. ALDATZE ETXADIA 21C - GALDAKAO (BIZKAIA) | BB16: =IF(A16="RESERVADO",S16,"LIBRE") | BC16: ES43 3035 0424 85 42410 36701
A17: RESERVADO | B17: 45356 | C17: 45383 | E17: 6 | F17: 1 | G17: 1 | H17: A | I17: 4 | J17: 9 | K17: 13 | L17: - | M17: . | N17: 111.09 | O17: 10.13 | P17: 121.22 | Q17: 142.57 | S17: 303400 | T17: 30340 | U17: 333740 | V17: 10012.2 | W17: 33374 | X17: 16687 | Y17: 30946.8 | Z17: 242720 | AA17: =AA16+2 | AB17: JOSE MARIA PRUDENCIO ALONSO | AF17: ANTONIA HERMOSA LOPEZ | AI17: hermosalopezantonia@gmail.com | AJ17: casados | AK17: C/. Castillo de Alconchel 26, 5, 1ºD | BB17: =IF(A17="RESERVADO",S17,"LIBRE") | BC17: ES54 2085 4508 3103 3145 5319
A18: RESERVADO | C18: 45903 | E18: 7 | F18: 1 | G18: 1 | H18: B | I18: 3 | J18: 12 | K18: 16 | L18: . | M18: . | N18: 93.26 | O18: 5.77 | P18: 99.03 | Q18: 115.43 | S18: 262000 | T18: 26200 | U18: 288200 | V18: 0 | W18: 34584 | X18: 8646 | Y18: 35370 | Z18: 209600 | AA18: =AA17+2 | AB18: ANA BELEN GOMEZ CABELLO | AE18: ana.cab.gom@hotmail.com | AJ18: soltera | AK18: C/ RAFAEL LUCENQUI 8, LOCAL ACADEMIA EDUCO 06004 | BB18: =IF(A18="RESERVADO",S18,"LIBRE") | BC18: ES71 1465 0100 9520 5664 0765
A19: RESERVADO | B19: 44720 | C19: 45415 | E19: 8 | F19: 1 | G19: 1 | H19: C | I19: 2 | J19: 54 | K19: 48 | L19: . | M19: . | N19: 71.38 | O19: 4.35 | P19: 75.73 | Q19: 87.48 | S19: 173818 | T19: 17381.8 | U19: 191199.8 | V19: 9724 | W19: 19119.99 | X19: 9396 | Y19: 13905.41 | Z19: 139054.4 | AA19: =AA18+2 | AB19: AMALIA CABANILLAS | AE19: amaliaahabilitados@gmail.com | AF19: PABLO JOSE DIAZ MARCOS | AI19: pablojosediaz@yahoo.es | AJ19: soltero | AK19: C/. Castillo de Zafra 3, 3ªB | AM19: no | AN19: 49 | AO19: Abogada | AP19: 1800 | AQ19: 47 | AR19: Empresario | AS19: 3000 | AT19: 0.8 | AU19: no | AV19: Reposición | AW19: Mejora | AX19: U. Guadiana | BB19: =IF(A19="RESERVADO",S19,"LIBRE") | BC19: ES17 1465 0100 94 1753450826
A20: RESERVADO | C20: 46008 | E20: 9 | F20: 1 | G20: 1 | H20: D | I20: 2 | J20: 10 | K20: 14 | L20: . | M20: . | N20: 64.33 | O20: 2.04 | P20: 66.37 | Q20: 77.92 | S20: 209000 | T20: 20900 | U20: 229900 | V20: 0 | W20: 34485 | X20: 0 | Y20: 28215 | Z20: 167200 | AA20: =AA19+2 | AB20: JACINTA GALLEGO SANCHEZ | AE20: jacintagallego20@gmail.com | AK20: C/. Julio Cinfuegos Linares 12, 3ºA - Badajoz | BB20: =IF(A20="RESERVADO",S20,"LIBRE")
A21: RESERVADO | B21: 45194 | C21: 45401 | E21: 10 | F21: 1 | G21: 1 | H21: E | I21: 2 | J21: 48 | K21: . | L21: . | M21: . | N21: 67.18 | O21: 3 | P21: 70.18 | Q21: 85.32 | S21: 178000 | T21: 17800 | U21: 195800 | V21: 6280 | W21: 19580 | X21: 9790 | Y21: 17750 | Z21: 142400 | AA21: =AA20+2 | AB21: VICTOR JOSE ROJAS MORENO | AE21: v.rojas@cnat.es | AK21: C/. Antonio Concha 78, 5, Navalmoral de la Mata (CC) | AN21: 45 | AO21: Trab. Central Nuclear | BB21: =IF(A21="RESERVADO",S21,"LIBRE") | BC21: ES04 0049 2522 6421 1509 5944
A22: RESERVADO | B22: …............ | C22: 45490 | E22: 11 | F22: 1 | G22: 1 | H22: F | I22: 2 | J22: 14 | K22: 21 | L22: . | M22: . | N22: 67.94 | O22: 3.62 | P22: 71.56 | Q22: 82.42 | S22: 185000 | T22: 18500 | U22: 203500 | V22: 0 | W22: 22385 | X22: 9157.5 | Y22: 23957.5 | Z22: 148000 | AA22: =AA21+2 | AB22: JUAN MANUEL DURAN GUERRERO | AE22: madugue@hotmail.com | AF22: MARIA JOSE JIMENEZ MURIEL | AK22: Travesia Arturo Barea 28, Merida (Badajoz) | BB22: =IF(A22="RESERVADO",S22,"LIBRE") | BC22: ES87 3009 0010 5221 1675 0429
A23: RESERVADO | B23: 44642 | C23: 45371 | E23: 12 | F23: 1 | G23: 2 | H23: A | I23: 4 | J23: 60 | K23: 54 | L23: . | M23: . | N23: 110.85 | O23: 10.78 | P23: 121.63 | Q23: 143.26 | S23: 279900 | T23: 27990 | U23: 307890 | V23: 9236.7 | W23: 30789 | X23: 15394.5 | Y23: 28549.8 | Z23: 223920 | AA23: =AA22+2 | AB23: IGNACIO AMARO BLANCO | AE23: iamaroblanco@gmail.com | AF23: ALBA GONZALEZ HABA MARTINEZ | AI23: alba.ghm@gmail.com | AJ23: casados | AK23: C/. Antonio de Nebrija, 6 A, 2 esc izq, 1ºB de Badajoz | AM23: no | AN23: 35 | AO23: Ing. Agronomo | AP23: 1800 | AQ23: 32 | AR23: Medico | AS23: 2200 | AT23: 0.8 | AU23: no | BB23: =IF(A23="RESERVADO",S23,"LIBRE") | BC23: ES55 0049 5525 5620 1103 8674
A24: RESERVADO | B24: 44669 | C24: 45383 | E24: 13 | F24: 1 | G24: 2 | H24: B | I24: 3 | J24: 13 | K24: 20 | L24: . | M24: . | N24: 93.39 | O24: 5.77 | P24: 99.16 | Q24: 115.43 | S24: 238600 | T24: 23860 | U24: 262460 | V24: 7873.8 | W24: 26246 | X24: 13123 | Y24: 24337.2 | Z24: 190880 | AA24: =AA23+2 | AB24: SATURNINO GONZALEZ -HABA GIL | AE24: ninoghg@gmail.com | AF24: MARIA ISABEL MARTINEZ FERNANDEZ | AI24: marisa63@educarex.es | AJ24: casados | AK24: C/. Condes de Cartagena 25, Villanueva de la Serena (Badajoz) | AM24: no | AN24: 56 | AO24: Profesor | AP24: 2400 | AQ24: 59 | AR24: Profesora | AS24: 2500 | AT24: 0.3 | AV24: reposición | AW24: para jubilacion | AX24: Otra localidad (hijos compran tambien) | BB24: =IF(A24="RESERVADO",S24,"LIBRE") | BC24: ES13 0049 5346 7123 1695 1598
A25: RESERVADO | B25: 44658 | C25: 45371 | E25: 14 | F25: 1 | G25: 2 | H25: C | I25: 2 | J25: 44 | K25: 43 | L25: . | M25: . | N25: 71.37 | O25: 4.35 | P25: 75.72 | Q25: 89.07 | S25: 178900 | T25: 17890 | U25: 196790 | V25: 9839.5 | W25: 19679 | X25: 9839.5 | Y25: 14312 | Z25: 143120 | AA25: =AA24+2 | AB25: JUAN FRANCISCO OTERO MARTIN | AE25: jfoteromartin@gmail.com | AF25: ---------------- | AJ25: divorciado | AK25: C/. Damian Tellez la Fuente 18, 4º D de Badajoz | AM25: no | AN25: 69 | AO25: Jubilado | AP25: 2100 | AT25: 0 | AU25: no | AV25: reposición | AW25: menor tamaño | AX25: Valdepasillas | BB25: =IF(A25="RESERVADO",S25,"LIBRE") | BC25: ES62 0049 4640 9022 9507 3949
A26: RESERVADO | C26: 45442 | E26: 15 | F26: 1 | G26: 2 | H26: D | I26: 2 | J26: 15 | K26: 22 | L26: . | M26: . | N26: 67.94 | O26: 3.1 | P26: 71.04 | Q26: 82.42 | S26: 185000 | T26: 18500 | U26: 203500 | V26: 0 | W26: 22385 | X26: 10175 | Y26: 22940 | Z26: 148000 | AA26: =AA25+2 | AB26: MARIA JESUS FERNANDEZ SANCHEZ | AE26: mariaj.fs.88@gmail.com | AJ26: soltera | AK26: C/. Camelia 15, 2ºC - Navalmoral de la Mata (Cáceres) | BB26: =IF(A26="RESERVADO",S26,"LIBRE") | BC26: ES58 0049 2522 6729 9586 4137
A27: RESERVADO | B27: 45336 | C27: 45392 | E27: 16 | F27: 1 | G27: 2 | H27: E | I27: 2 | J27: 58 | K27: 51 | N27: 64.07 | O27: 2.68 | P27: 66.75 | Q27: 85.32 | S27: 181000 | T27: 18100 | U27: 199100 | V27: 5973 | W27: 19910 | X27: 9955 | Y27: 18462 | Z27: 144800 | AA27: =AA26+2 | AB27: MANUEL JOSE SUAREZ MARTIN | AE27: pepe.jerepe83@gmail.com | AK27: C/. Diputación 25, Monterrubio de la Serena (Badajoz) | AN27: 40 | BB27: =IF(A27="RESERVADO",S27,"LIBRE") | BC27: ES65 0078 0059 3240 1000 2962
A28: RESERVADO | C28: 45504 | E28: 17 | F28: 1 | G28: 2 | H28: F | I28: 2 | J28: 43 | K28: 42 | L28: . | M28: . | N28: 67.94 | O28: 3.1 | P28: 71.04 | Q28: 82.42 | S28: 187000 | T28: 18700 | U28: 205700 | V28: 0 | W28: 22627 | X28: 8228 | Y28: 25245 | Z28: 149600 | AA28: =AA27+2 | AB28: MARIA DURAN ENTISNE | AE28: maria.despachoduran@gmail.com | AJ28: soltera | AK28: C/. Conde Barcelona 9, 5º A - Badajoz | BB28: =IF(A28="RESERVADO",S28,"LIBRE") | BC28: ES97 3009 0091 8021 1575 2517
A29: RESERVADO | B29: 44642 | C29: 45383 | E29: 18 | F29: 1 | G29: 3 | H29: A | I29: 4 | J29: 59 | K29: 53 | L29: 50 | M29: . | N29: 110.85 | O29: 11.4 | P29: 122.25 | Q29: 140.49 | S29: 300100 | T29: 30010 | U29: 330110 | V29: 16605.5 | W29: 33011 | X29: 14000 | Y29: 26413.5 | Z29: 240080 | AA29: =AA28+2 | AB29: DIEGO GARCIA RUBIO | AE29: miotracuenta2@gmail.com | AF29: SARA ESPINA HIDALGO | AI29: sespinah@gmai.com | AJ29: casados | AK29: C/. Castillo Puebla de Alcocer, 32, 2ºA de Badajoz | AM29: hijos | AN29: 58 | AO29: Veterinario | AP29: 2300 | AQ29: 56 | AR29: Bibliotecaria | AS29: 2500 | AT29: 0.8 | AU29: consideraran | AV29: Reposición | AX29: U. Guadiana | BB29: =IF(A29="RESERVADO",S29,"LIBRE") | BC29: ES33 0049 0373 6025 9167 2500
A30: RESERVADO | B30: 44650 | C30: 45386 | E30: 19 | F30: 1 | G30: 3 | H30: B | I30: 3 | J30: 16 | K30: 23 | L30: . | M30: . | N30: 93.39 | O30: 5.77 | P30: 99.16 | Q30: 115.43 | S30: 239700 | T30: 23970 | U30: 263670 | V30: 14184 | W30: 25367 | X30: 13183 | Y30: 19176 | Z30: 191760 | AA30: =AA29+2 | AB30: FELIPA PEREZ CORRALES | AE30: felipaperezcorrales@gmail.com | AK30: C/. Madame Curie 209, 1ºB de Cáceres | AM30: no | AN30: 63 | AO30: Funcionario | AP30: 1500 | AT30: 0 | AU30: no | AV30: Reposicion | AX30: Otra localidad (Cáceres) | BB30: =IF(A30="RESERVADO",S30,"LIBRE") | BC30: ES60 3009 0110 9628 2475 4325
A31: RESERVADO | B31: 44648 | C31: 45383 | E31: 20 | F31: 1 | G31: 3 | H31: C | I31: 2 | J31: 38 | K31: 25 | L31: . | M31: . | N31: 71.37 | O31: 2.54 | P31: 73.91 | Q31: 87.14 | R31: 3.62 | S31: 181600 | T31: 18160 | U31: 199760 | V31: 9988 | W31: 19976 | X31: 9988 | Y31: 14528 | Z31: 145280 | AA31: =AA30+2 | AB31: PAULINO CONEJO NAVARRETE | AE31: paulino.conejo@hotmail.com | AF31: ---------------- | AJ31: casado | AK31: Plaza de la Constitución 2, 1ºAB de Badajoz | AN31: 72 | AO31: jubilado | AT31: 0 | AU31: no | AV31: Inversión | AX31: Pardaleras | BB31: =IF(A31="RESERVADO",S31,"LIBRE") | BC31: ES30 2080 3578 80030 4008 5577
A32: RESERVADO | B32: 44874 | C32: 45383 | E32: 21 | F32: 1 | G32: 3 | H32: D | I32: 2 | J32: 45 | K32: 44 | L32: . | M32: . | N32: 67.94 | O32: 3.1 | P32: 71.04 | Q32: 82.42 | S32: 184000 | T32: 18400 | U32: 202400 | V32: 10120 | W32: 20240 | X32: 10120 | Y32: 14720 | Z32: 147200 | AA32: =AA31+2 | AB32: PAULINO CONEJO NAVARRETE | AE32: paulino.conejo@hotmail.com | AF32: ---------------- | AJ32: casado | AK32: Plaza de la Constitución 2, 1ºAB de Badajoz | AN32: 72 | AO32: jubilado | AT32: 0 | AU32: no | AV32: Inversión | AX32: Pardaleras | BB32: =IF(A32="RESERVADO",S32,"LIBRE") | BC32: ES30 2080 3578 80030 4008 5577
A33: RESERVADO | B33: 45330 | C33: 45397 | E33: 22 | F33: 1 | G33: 3 | H33: E | I33: 2 | J33: 11 | K33: 15 | L33: . | M33: . | N33: 64.07 | O33: 2.68 | P33: 66.75 | Q33: 85.32 | S33: 184000 | T33: 18400 | U33: 202400 | V33: 6072 | W33: 20240 | X33: 10120 | Y33: 18768 | Z33: 147200 | AA33: =AA32+2 | AB33: TRINIDAD VILLALOBOS SAAVEDRA | AE33: trivillasa@gmail.com | AF33: ….............. | AK33: Av. Miguel Angel Celdran Matu, 14 -4ºIz, Badajoz | BB33: =IF(A33="RESERVADO",S33,"LIBRE") | BC33: ES06 0182 2874 0502 0158 0919
A34: RESERVADO | B34: 44874 | C34: 45397 | E34: 23 | F34: 1 | G34: 3 | H34: F | I34: 2 | J34: 51 | K34: 46 | L34: . | M34: . | N34: 67.94 | O34: 3.1 | P34: 71.04 | Q34: 82.42 | S34: 184000 | T34: 18400 | U34: 202400 | V34: 10120 | W34: 20240 | X34: 10120 | Y34: 14720 | Z34: 147200 | AA34: =AA33+2 | AB34: MARIA JOSEFA MANCHADO MORAGA | AE34: majosevva@gmail.com | AF34: MIGUEL ANGEL GARCIA OLIVARES | AJ34: casado | AK34: C/. Eduardo Pino 21 de Villanueva de la Serena (Badajoz) | AM34: hios | AN34: 49 | AO34: Profesora | AP34: 2300 | AQ34: 51 | AR34: Autonomo | AS34: 1800 | AT34: 0.4 | AU34: no | AV34: Inversión | AX34: Otra localidad (Villanueva) | BB34: =IF(A34="RESERVADO",S34,"LIBRE") | BC34: ES76 0078 0035 02 401000 6986
A35: RESERVADO | B35: 44638 | C35: 45412 | E35: 24 | F35: 1 | G35: 4 | H35: A | I35: 4 | J35: 41 | K35: 52 | L35: . | M35: . | N35: 97.99 | O35: 4.61 | P35: 102.6 | Q35: 119.19 | R35: 29.99 | S35: 276600 | T35: 27660 | U35: 304260 | V35: 15213 | W35: 30426 | X35: 15213 | Y35: 22128 | Z35: 221280 | AA35: =AA34+2 | AB35: SERVILIANO VALENCIA DIAZ | AE35: servilianovd@gmail.com | AF35: RAQUEL VIZUETE GONZALEZ | AI35: raquelvizuete@hotmail.com | AJ35: Casados | AK35: C/. Julio Cienfugos Linares 10, Derecha, 3º B de Badajoz | AM35: Hijos | AN35: 47 | AO35: Guardia Civil | AP35: 2100 | AQ35: 47 | AR35: Técnico operación aérea | AS35: 1900 | AT35: 0.8 | AU35: consideraran | AV35: Reposición | AW35: Más grande | AX35: Jardines | BB35: =IF(A35="RESERVADO",S35,"LIBRE") | BC35: ES29 1465 0100 92 1729779798
A36: RESERVADO | B36: 45343 | C36: 45383 | E36: 25 | F36: 1 | G36: 4 | H36: B | I36: 2 | J36: 8 | K36: 12 | L36: . | M36: . | N36: 67.94 | O36: 3.1 | P36: 71.04 | Q36: 82.42 | S36: 189900 | T36: 18990 | U36: 208890 | V36: 6266.7 | W36: 20899 | X36: 10444.5 | Y36: 19359.8 | Z36: 151920 | AA36: =AA35+2 | AB36: ANTONIO SANTIAGO ROMERO | AE36: ansaro7@outlook.es | AF36: ANGELA IGLESIAS DOMINGUEZ | AJ36: Casados | AK36: C/. De la Cebada 7, Cáceres | AN36: 64 | AO36: jubilado | AQ36: 68 | AR36: jubilado | AT36: 0 | AU36: no | AW36: Res. Ocasional | AX36: Cáceres | BB36: =IF(A36="RESERVADO",S36,"LIBRE") | BC36: ES57 0182 0395 8402 0000 5781
A37: RESERVADO | B37: 45336 | C37: 45392 | E37: 26 | F37: 1 | G37: 4 | H37: C | I37: 2 | J37: 65 | K37: 59 | L37: . | M37: . | N37: 64.07 | O37: 2.68 | P37: 66.75 | Q37: 85.32 | S37: 187000 | T37: 18700 | U37: 205700 | V37: 6171 | W37: 20570 | X37: 10285 | Y37: 19074 | Z37: 149600 | AA37: =AA36+2 | AB37: VICENTE MIGUEL SUAREZ MARTIN | AK37: C/. Diputación 5, Monterrubio de la Serena (Badajoz) | AN37: 53 | BB37: =IF(A37="RESERVADO",S37,"LIBRE") | BC37: ES39 2103 7308 9300 1003 9384
A38: RESERVADO | B38: 45319 | C38: 45392 | E38: 27 | F38: 1 | G38: 4 | H38: D | I38: 2 | J38: 53 | K38: 19 | L38: . | M38: . | N38: 67.94 | O38: 3.1 | P38: 71.04 | Q38: 82.42 | S38: 189900 | T38: 18990 | U38: 208890 | V38: 6266.7 | W38: 20889 | X38: 10444.5 | Y38: 19369.8 | Z38: 151920 | AA38: =AA37+2 | AB38: ELENA SANCHEZ RICO | AE38: eschzrico@gmail.com | AF38: …................ | AI38: …........... | AJ38: soltera | AK38: C/. Julia Urdiain Zubelzu 3; bloque 2, 3º D de Badajoz | AM38: no | AO38: policias nac. | BB38: =IF(A38="RESERVADO",S38,"LIBRE") | BC38: ES38 0182 2874 0102 0165 1640
A39: RESERVADO | B39: 44638 | C39: 45405 | E39: 28 | F39: 1 | G39: 5 | H39: A | I39: 4 | J39: 52 | K39: 47 | L39: 49 | M39: . | N39: 97.99 | O39: 0 | P39: 97.99 | Q39: 114.66 | R39: 13.1 | S39: 270415 | T39: 27041.5 | U39: 297456.5 | V39: 0 | W39: 83709.97 | X39: 5250 | Y39: 18750.03 | Z39: 189746.5 | AA39: =AA38+2 | AB39: JOE MANUEL ROMERO MATOS | AE39: jmromeromatos@gmail.com | AF39: ---------------- | AK39: C/. Antonio de Nebrija, 6 A, 2ºB - 06006 Badajoz | AT39: 0.5 | AV39: Reposición | AX39: Jardines | BB39: =IF(A39="RESERVADO",S39,"LIBRE") | BC39: ES40 2100 2194 7602 0026 4280 | BD39: ES44 2100 2194 7302 0034 6320
A40: RESERVADO | C40: 45898 | E40: 29 | F40: 1 | G40: 5 | H40: B | I40: 4 | J40: 19 | K40: 27 | L40: . | M40: . | N40: 113.23 | O40: 3.88 | P40: 117.11 | Q40: 134.23 | R40: 7.8 | S40: 305000 | T40: 30500 | U40: 335500 | V40: 0 | W40: 40260 | X40: 10065 | Y40: 41175 | Z40: 244000 | AA40: =AA39+2 | AB40: SANTIAGO TOLOSA ALVAREZ | AE40: santi.tolosa.alvarez@gmail.com | AJ40: soltero | AK40: C/. Martires 56, 2ºIz - Almendralejo (Badajoz) | BB40: =IF(A40="RESERVADO",S40,"LIBRE") | BC40: ES72 1586 0001 4308 8600 0511
A41: RESERVADO | B41: 44662 | C41: 45411 | E41: 30 | F41: 1 | G41: 5 | H41: C | I41: 4 | J41: 46 | K41: 45 | L41: . | M41: . | N41: 112.01 | O41: 3.88 | P41: 115.89 | Q41: 134.04 | R41: 7.8 | S41: 271400 | T41: 27140 | U41: 298540 | V41: 14927 | W41: 29854 | X41: 14927 | Y41: 21712 | Z41: 217120 | AA41: =AA40+2 | AB41: ANGEL GUTIERREZ ROBLES | AE41: angelgutiez@gmail.com | AF41: DOLORES ALBA GARCIA | AI41: albatecnico@hotmail.com | AJ41: casados en separación de bienes | AK41: C/. Francisco Guerra 16, 2ºD de Badajoz | AM41: si | AN41: 47 | AO41: Ingeniero Sof. | AP41: 2100 | AQ41: 45 | AR41: Funcionaria | AS41: 2200 | AT41: 0.8 | AU41: consideraran | AV41: Reposición | AX41: La Paz | BB41: =IF(A41="RESERVADO",S41,"LIBRE") | BC41: ES36 0049 5953 2621 1620 7535
A42: RESERVADO | C42: 46006 | E42: 31 | F42: 2 | G42: BAJA | H42: A | I42: 5 | J42: 22 | K42: 30 | L42: . | M42: . | N42: 136.79 | O42: 9.46 | P42: 146.25 | Q42: 167.59 | R42: 27.56 | S42: 380000 | T42: 38000 | U42: 418000 | V42: 0 | W42: 62700 | X42: 0 | Y42: 51300 | Z42: 304000 | AA42: =AA41+2 | AB42: MARIA DE LOS ANGELES NAVARRETE GOMEZ | AE42: maria.navarreteg@salud-juntaex.es | BB42: =IF(A42="RESERVADO",S42,"LIBRE")
A43: DISPONIBLE | E43: 32 | F43: 2 | G43: BAJA | H43: B | I43: 4 | J43: 21 | K43: 29 | L43: . | M43: . | N43: 111.63 | O43: 9.64 | P43: 121.27 | Q43: 138.9 | R43: 31.74 | S43: 318200 | T43: 31820 | U43: 350020 | V43: 0 | W43: 38184 | X43: 9546 | Y43: 47730 | Z43: 254560 | AA43: =AA42+2 | BB43: =IF(A43="RESERVADO",S43,"LIBRE")
A44: RESERVADO | B44: 25/19/22 | C44: 45383 | E44: 33 | F44: 2 | G44: BAJA | H44: C | I44: 3 | J44: 33 | K44: 5 | L44: . | M44: . | N44: 95.02 | O44: 5.35 | P44: 100.37 | Q44: 116.06 | R44: 42.63 | S44: 245700 | T44: 24570 | U44: 270270 | V44: 10000 | W44: 20000 | X44: 13513.5 | Y44: 30196.5 | Z44: 196560 | AA44: =AA43+2 | AB44: CLAUDIO BORREGO DOMÍNGUEZ | AE44: claudio.borrego@gmail.com | AF44: MARIA TERESA REAL CARRILLO | AI44: real.maite@gmail.com | AJ44: casados | AK44: C/. Castillo de Olivenza 20 de Badajoz | AM44: no | AN44: 63 | AQ44: 61 | AT44: 0 | AU44: si | AV44: Reposción | AW44: Menor tamaño | AX44: U. Guadiana | BB44: =IF(A44="RESERVADO",S44,"LIBRE") | BC44: ES36 0182 5877 1202 0159 8666
A45: BLOQUEADO | E45: 34 | F45: 2 | G45: BAJA | H45: D | I45: 2 | J45: 20 | K45: 28 | L45: . | M45: . | N45: 59.02 | O45: 4.36 | P45: 63.38 | Q45: 75.23 | R45: 45.06 | S45: 183300 | T45: 18330 | U45: 201630 | V45: 0 | W45: 0 | X45: 0 | Y45: 54990 | Z45: 146640 | AA45: =AA44+2 | BB45: =IF(A45="RESERVADO",S45,"LIBRE")
...

Sheet MEJORAS
B1: IMPORTES MEJORAS
B6: Nº Orden | C6: VIVIENDA | F6: TITULAR 1 | G6: PRECIO | J6: FORMA DE PAGO ESTANDAR (IVA inlcuido) | N6: PORCELANICO | O6: IVA PORCELÁNICO | P6: TOTAL PORCELÁNICO | Q6: TOTAL IMPORTE MEJORAS (SIN IVA) | R6: TOTAL IMPORTE MEJORAS (CON IVA)
C7: PORTAL | D7: PLANTA | E7: LETRA | G7: Neto | H7: IVA | I7: TOTAL 1 | J7: PAGO INICIAL | K7: Resto | L7: nº pagos | M7: importe individual pagos
B9: 1 | C9: 1 | D9: BAJA | E9: A | F9: =+'SITUACION COMERCIAL'!AB12 | G9: 5625 | H9: =+G9*0.1 | I9: =+H9+G9 | J9: =+I9-K9 | K9: =+M9*L9 | L9: 19 | M9: 195.39 | N9: =+'TOTAL OPERACION'!R10 | O9: =N9*0.1 | P9: =N9+O9 | Q9: =N9+G9 | R9: =P9+I9
B10: =+B9+1 | C10: 1 | D10: BAJA | E10: B | F10: =+'SITUACION COMERCIAL'!AB13 | G10: 1775 | H10: =+G10*0.1 | I10: =+H10+G10 | J10: =+I10-K10 | K10: =+M10*L10 | L10: 19 | M10: 61.65 | N10: =+'TOTAL OPERACION'!R11 | O10: =N10*0.1 | P10: =N10+O10 | Q10: =N10+G10 | R10: =P10+I10
B11: 3 | C11: 1 | D11: BAJA | E11: C | F11: =+'SITUACION COMERCIAL'!AB14 | H11: =+G11*0.1 | I11: =+H11+G11 | L11: 20 | N11: =+'TOTAL OPERACION'!R12 | O11: =N11*0.1 | P11: =N11+O11 | Q11: =N11+G11 | R11: =P11+I11
B12: =+B11+1 | C12: 1 | D12: BAJA | E12: D | F12: =+'SITUACION COMERCIAL'!AB15 | G12: 1250 | H12: =+G12*0.1 | I12: =+H12+G12 | J12: 550.06 | K12: =+L12*M12 | L12: 18 | M12: 45.83 | N12: =+'TOTAL OPERACION'!R13 | O12: =N12*0.1 | P12: =N12+O12 | Q12: =N12+G12 | R12: =P12+I12
B13: =+B12+1 | C13: 1 | D13: BAJA | E13: E | F13: =+'SITUACION COMERCIAL'!AB28 | H13: =+G13*0.1 | I13: =+H13+G13 | L13: 20 | N13: =+'TOTAL OPERACION'!R14 | O13: =N13*0.1 | P13: =N13+O13 | Q13: =N13+G13 | R13: =P13+I13
B14: =+B13+1 | C14: 1 | D14: 1 | E14: A | F14: =+'SITUACION COMERCIAL'!AB17 | G14: 2465 | H14: =+G14*0.1 | I14: =+H14+G14 | J14: =+I14-K14 | K14: =+M14*L14 | L14: 19 | M14: 85.62 | N14: =+'TOTAL OPERACION'!R15 | O14: =N14*0.1 | P14: =N14+O14 | Q14: =N14+G14 | R14: =P14+I14
B15: =+B14+1 | C15: 1 | D15: 1 | E15: B | F15: =+'SITUACION COMERCIAL'!AB18 | H15: =+G15*0.1 | I15: =+H15+G15 | L15: 20 | N15: =+'TOTAL OPERACION'!R16 | O15: =N15*0.1 | P15: =N15+O15 | Q15: =N15+G15 | R15: =P15+I15
B16: =+B15+1 | C16: 1 | D16: 1 | E16: C | F16: =+'SITUACION COMERCIAL'!AB19 | H16: =+G16*0.1 | I16: =+H16+G16 | L16: 20 | N16: =+'TOTAL OPERACION'!R17 | O16: =N16*0.1 | P16: =N16+O16 | Q16: =N16+G16 | R16: =P16+I16
B17: =+B16+1 | C17: 1 | D17: 1 | E17: D | F17: =+'SITUACION COMERCIAL'!AB20 | H17: =+G17*0.1 | I17: =+H17+G17 | L17: 20 | N17: =+'TOTAL OPERACION'!R18 | O17: =N17*0.1 | P17: =N17+O17 | Q17: =N17+G17 | R17: =P17+I17
B18: =+B17+1 | C18: 1 | D18: 1 | E18: E | F18: =+'SITUACION COMERCIAL'!AB21 | G18: 685 | H18: =+G18*0.1 | I18: =+H18+G18 | J18: 753.5 | L18: 20 | N18: =+'TOTAL OPERACION'!R19 | O18: =N18*0.1 | P18: =N18+O18 | Q18: =N18+G18 | R18: =P18+I18
B19: =+B18+1 | C19: 1 | D19: 1 | E19: F | F19: =+'SITUACION COMERCIAL'!AB22 | H19: =+G19*0.1 | I19: =+H19+G19 | L19: 20 | N19: =+'TOTAL OPERACION'!R20 | O19: =N19*0.1 | P19: =N19+O19 | Q19: =N19+G19 | R19: =P19+I19
B20: =+B19+1 | C20: 1 | D20: 2 | E20: A | F20: =+'SITUACION COMERCIAL'!AB23 | G20: =2015+90 | H20: =+G20*0.1 | I20: =+H20+G20 | J20: 886.5 | K20: =+M20*L20 | L20: 19 | M20: 75.21 | N20: =+'TOTAL OPERACION'!R21 | O20: =N20*0.1 | P20: =N20+O20 | Q20: =N20+G20 | R20: =P20+I20
B21: =+B20+1 | C21: 1 | D21: 2 | E21: B | F21: =+'SITUACION COMERCIAL'!AB24 | G21: 2610 | H21: =+G21*0.1 | I21: =+H21+G21 | J21: 1148.46 | K21: =+M21*L21 | L21: 19 | M21: =1722.54/19 | N21: =+'TOTAL OPERACION'!R22 | O21: =N21*0.1 | P21: =N21+O21 | Q21: =N21+G21 | R21: =P21+I21
B22: =+B21+1 | C22: 1 | D22: 2 | E22: C | F22: =+'SITUACION COMERCIAL'!AB25 | G22: 495 | H22: =+G22*0.1 | I22: =+H22+G22 | J22: =+I22 | L22: 20 | N22: =+'TOTAL OPERACION'!R23 | O22: =N22*0.1 | P22: =N22+O22 | Q22: =N22+G22 | R22: =P22+I22
B23: =+B22+1 | C23: 1 | D23: 2 | E23: D | F23: =+'SITUACION COMERCIAL'!AB26 | G23: 1185 | H23: =+G23*0.1 | I23: =+H23+G23 | J23: 524.5 | K23: =+M23*L23 | L23: 19 | M23: 41 | N23: =+'TOTAL OPERACION'!R24 | O23: =N23*0.1 | P23: =N23+O23 | Q23: =N23+G23 | R23: =P23+I23
B24: =+B23+1 | C24: 1 | D24: 2 | E24: E | F24: =+'SITUACION COMERCIAL'!AB27 | G24: 1250 | H24: =+G24*0.1 | I24: =+H24+G24 | J24: 500 | K24: =+M24*L24+0.02 | L24: 18 | M24: 48.61 | N24: =+'TOTAL OPERACION'!R25 | O24: =N24*0.1 | P24: =N24+O24 | Q24: =N24+G24 | R24: =P24+I24
B25: =+B24+1 | C25: 1 | D25: 2 | E25: F | F25: =+'SITUACION COMERCIAL'!#REF! | H25: =+G25*0.1 | I25: =+H25+G25 | L25: 20 | N25: =+'TOTAL OPERACION'!R26 | O25: =N25*0.1 | P25: =N25+O25 | Q25: =N25+G25 | R25: =P25+I25
B26: =+B25+1 | C26: 1 | D26: 3 | E26: A | F26: =+'SITUACION COMERCIAL'!AB29 | G26: 3800 | H26: =+G26*0.1 | I26: =+H26+G26 | J26: 1672 | K26: =+M26*L26 | L26: 19 | M26: 132 | N26: =+'TOTAL OPERACION'!R27 | O26: =N26*0.1 | P26: =N26+O26 | Q26: =N26+G26 | R26: =P26+I26
B27: =+B26+1 | C27: 1 | D27: 3 | E27: B | F27: =+'SITUACION COMERCIAL'!AB30 | G27: 1880 | H27: =+G27*0.1 | I27: =+H27+G27 | J27: 827.3 | L27: 19 | M27: 65.3 | N27: =+'TOTAL OPERACION'!R28 | O27: =N27*0.1 | P27: =N27+O27 | Q27: =N27+G27 | R27: =P27+I27
B28: =+B27+1 | C28: 1 | D28: 3 | E28: C | F28: =+'SITUACION COMERCIAL'!AB31 | G28: 0 | H28: =+G28*0.1 | I28: =+H28+G28 | L28: 20 | N28: =+'TOTAL OPERACION'!R29 | O28: =N28*0.1 | P28: =N28+O28 | Q28: =N28+G28 | R28: =P28+I28
B29: =+B28+1 | C29: 1 | D29: 3 | E29: D | F29: =+'SITUACION COMERCIAL'!AB32 | G29: 0 | H29: =+G29*0.1 | I29: =+H29+G29 | L29: 20 | N29: =+'TOTAL OPERACION'!R30 | O29: =N29*0.1 | P29: =N29+O29 | Q29: =N29+G29 | R29: =P29+I29
B30: =+B29+1 | C30: 1 | D30: 3 | E30: E | F30: =+'SITUACION COMERCIAL'!AB33 | G30: 1540 | H30: =+G30*0.1 | I30: =+H30+G30 | J30: 677.72 | L30: 18 | M30: 56.46 | N30: =+'TOTAL OPERACION'!R31 | O30: =N30*0.1 | P30: =N30+O30 | Q30: =N30+G30 | R30: =P30+I30
B31: =+B30+1 | C31: 1 | D31: 3 | E31: F | F31: =+'SITUACION COMERCIAL'!AB34 | G31: 1125 | H31: =+G31*0.1 | I31: =+H31+G31 | J31: 495 | K31: =+M31*L31 | L31: 18 | M31: 41.25 | N31: =+'TOTAL OPERACION'!R32 | O31: =N31*0.1 | P31: =N31+O31 | Q31: =N31+G31 | R31: =P31+I31
B32: =+B31+1 | C32: 1 | D32: 4 | E32: A | F32: =+'SITUACION COMERCIAL'!AB35 | G32: 3345 | H32: =+G32*0.1 | I32: =+H32+G32 | J32: 735.9 | K32: =+M32*L32 | L32: 15 | M32: 196.24 | N32: =+'TOTAL OPERACION'!R33 | O32: =N32*0.1 | P32: =N32+O32 | Q32: =N32+G32 | R32: =P32+I32
B33: =+B32+1 | C33: 1 | D33: 4 | E33: B | F33: =+'SITUACION COMERCIAL'!AB36 | G33: 1385 | H33: =+G33*0.1 | I33: =+H33+G33 | J33: 609.4 | K33: =+M33*L33 | L33: 19 | M33: 48.11 | N33: =+'TOTAL OPERACION'!R34 | O33: =N33*0.1 | P33: =N33+O33 | Q33: =N33+G33 | R33: =P33+I33
B34: =+B33+1 | C34: 1 | D34: 4 | E34: C | F34: =+'SITUACION COMERCIAL'!AB37 | G34: 1250 | H34: =+G34*0.1 | I34: =+H34+G34 | J34: 500 | K34: 875 | L34: 18 | M34: 48.61 | N34: =+'TOTAL OPERACION'!R35 | O34: =N34*0.1 | P34: =N34+O34 | Q34: =N34+G34 | R34: =P34+I34
B35: =+B34+1 | C35: 1 | D35: 4 | E35: D | F35: =+'SITUACION COMERCIAL'!AB38 | G35: 1070 | H35: =+G35*0.1 | I35: =+H35+G35 | J35: 470.96 | K35: =+L35*M35 | L35: 19 | M35: 37.16 | N35: =+'TOTAL OPERACION'!R36 | O35: =N35*0.1 | P35: =N35+O35 | Q35: =N35+G35 | R35: =P35+I35
B36: =+B35+1 | C36: 1 | D36: 5 | E36: A | F36: =+'SITUACION COMERCIAL'!AB39 | G36: 2715 | H36: =+G36*0.1 | I36: =+H36+G36 | J36: 2986.5 | L36: 20 | N36: =+'TOTAL OPERACION'!R37 | O36: =N36*0.1 | P36: =N36+O36 | Q36: =N36+G36 | R36: =P36+I36
B37: =+B36+1 | C37: 1 | D37: 5 | E37: B | F37: =+'SITUACION COMERCIAL'!AB40 | H37: =+G37*0.1 | I37: =+H37+G37 | L37: 20 | N37: =+'TOTAL OPERACION'!R38 | O37: =N37*0.1 | P37: =N37+O37 | Q37: =N37+G37 | R37: =P37+I37
B38: =+B37+1 | C38: 1 | D38: 5 | E38: C | F38: =+'SITUACION COMERCIAL'!AB41 | G38: 0 | H38: =+G38*0.1 | I38: =+H38+G38 | L38: 20 | N38: =+'TOTAL OPERACION'!R39 | O38: =N38*0.1 | P38: =N38+O38 | Q38: =N38+G38 | R38: =P38+I38
B39: =+B38+1 | C39: 2 | D39: BAJA | E39: A | F39: =+'SITUACION COMERCIAL'!AB42 | H39: =+G39*0.1 | I39: =+H39+G39 | L39: 20 | N39: =+'TOTAL OPERACION'!R40 | O39: =N39*0.1 | P39: =N39+O39 | Q39: =N39+G39 | R39: =P39+I39
B40: =+B39+1 | C40: 2 | D40: BAJA | E40: B | F40: =+'SITUACION COMERCIAL'!AB43 | H40: =+G40*0.1 | I40: =+H40+G40 | L40: 20 | N40: =+'TOTAL OPERACION'!R41 | O40: =N40*0.1 | P40: =N40+O40 | Q40: =N40+G40 | R40: =P40+I40
B41: =+B40+1 | C41: 2 | D41: BAJA | E41: C | F41: =+'SITUACION COMERCIAL'!AB44 | G41: 3280 | H41: =+G41*0.1 | I41: =+H41+G41 | J41: =+I41*0.4-0.06 | K41: =+M41*L41 | L41: 19 | M41: 113.94 | N41: =+'TOTAL OPERACION'!R42 | O41: =N41*0.1 | P41: =N41+O41 | Q41: =N41+G41 | R41: =P41+I41
B42: =+B41+1 | C42: 2 | D42: BAJA | E42: D | F42: =+'SITUACION COMERCIAL'!AB45 | H42: =+G42*0.1 | I42: =+H42+G42 | L42: 20 | N42: =+'TOTAL OPERACION'!R43 | O42: =N42*0.1 | P42: =N42+O42 | Q42: =N42+G42 | R42: =P42+I42
B43: =+B42+1 | C43: 2 | D43: BAJA | E43: E | F43: =+'SITUACION COMERCIAL'!AB46 | G43: 875 | H43: =+G43*0.1 | I43: =+H43+G43 | J43: =+I43*0.4-0.1 | K43: =+M43*19 | L43: 19 | M43: 30.4 | N43: =+'TOTAL OPERACION'!R44 | O43: =N43*0.1 | P43: =N43+O43 | Q43: =N43+G43 | R43: =P43+I43
B44: =+B43+1 | C44: 2 | D44: 1 | E44: A | F44: =+'SITUACION COMERCIAL'!AB47 | G44: 0 | H44: =+G44*0.1 | I44: =+H44+G44 | L44: 20 | N44: =+'TOTAL OPERACION'!R45 | O44: =N44*0.1 | P44: =N44+O44 | Q44: =N44+G44 | R44: =P44+I44
B45: =+B44+1 | C45: 2 | D45: 1 | E45: B | F45: =+'SITUACION COMERCIAL'!AB48 | G45: 1855 | H45: =+G45*0.1 | I45: =+H45+G45 | J45: =+I45*0.4+0.13 | K45: =+M45*L45 | L45: 19 | M45: 64.43 | N45: =+'TOTAL OPERACION'!R46 | O45: =N45*0.1 | P45: =N45+O45 | Q45: =N45+G45 | R45: =P45+I45
...

Sheet TOTAL OPERACION
C1: IMPORTES TOTALES OPERACIÓN
C6: TITULAR 1 | G6: INMUEBLES | P6: PRECIOS
G7: Nº Orden | H7: VIVIENDA | L7: ANEXOS | P7: VIVIENDA | Q7: MEJORAS | R7: PORCELANICO | S7: TOTAL
H8: PORTAL | I8: PLANTA | J8: LETRA | K8: Nº Dorm. | L8: Garaje | M8: Trastero | N8: G. Adicional | O8: Tr. Adicional
C10: =+'SITUACION COMERCIAL'!AB12 | G10: 1 | H10: 1 | I10: BAJA | J10: A | K10: 4 | L10: 62 | M10: 56 | N10: . | O10: . | P10: =+'SITUACION COMERCIAL'!S12 | Q10: =+MEJORAS!G9 | R10: 4300 | S10: =+P10+Q10+R10
C11: =+'SITUACION COMERCIAL'!AB13 | G11: =+G10+1 | H11: 1 | I11: BAJA | J11: B | K11: 3 | L11: 57 | M11: 50 | N11: . | O11: . | P11: =+'SITUACION COMERCIAL'!S13 | Q11: =+MEJORAS!G10 | S11: =+P11+Q11+R11
C12: =+'SITUACION COMERCIAL'!AB14 | G12: 3 | H12: 1 | I12: BAJA | J12: C | K12: 2 | L12: NO | M12: 49 | N12: . | P12: =+'SITUACION COMERCIAL'!S14 | Q12: =+MEJORAS!G11 | S12: =+P12+Q12+R12
C13: =+'SITUACION COMERCIAL'!AB15 | G13: =+G12+1 | H13: 1 | I13: BAJA | J13: D | K13: 2 | L13: 40 | M13: 60 | N13: . | O13: . | P13: =+'SITUACION COMERCIAL'!S15 | Q13: =+MEJORAS!G12 | S13: =+P13+Q13+R13
C14: =+'SITUACION COMERCIAL'!AB28 | G14: =+G13+1 | H14: 1 | I14: BAJA | J14: E | K14: 2 | L14: 43 | M14: 18 | N14: . | O14: . | P14: =+'SITUACION COMERCIAL'!S16 | Q14: =+MEJORAS!G13 | S14: =+P14+Q14+R14
C15: =+'SITUACION COMERCIAL'!AB17 | G15: =+G14+1 | H15: 1 | I15: 1 | J15: A | K15: 4 | L15: 9 | M15: 13 | N15: - | O15: . | P15: =+'SITUACION COMERCIAL'!S17 | Q15: =+MEJORAS!G14 | R15: 4300 | S15: =+P15+Q15+R15
C16: =+'SITUACION COMERCIAL'!AB18 | G16: =+G15+1 | H16: 1 | I16: 1 | J16: B | K16: 3 | L16: 12 | M16: 16 | N16: . | O16: . | P16: =+'SITUACION COMERCIAL'!S18 | Q16: =+MEJORAS!G15 | S16: =+P16+Q16+R16
C17: =+'SITUACION COMERCIAL'!AB19 | G17: =+G16+1 | H17: 1 | I17: 1 | J17: C | K17: 2 | L17: 54 | M17: 48 | N17: . | O17: . | P17: =+'SITUACION COMERCIAL'!S19 | Q17: =+MEJORAS!G16 | R17: 2850 | S17: =+P17+Q17+R17
C18: =+'SITUACION COMERCIAL'!AB20 | G18: =+G17+1 | H18: 1 | I18: 1 | J18: D | K18: 2 | L18: 10 | M18: 14 | N18: . | O18: . | P18: =+'SITUACION COMERCIAL'!S20 | Q18: =+MEJORAS!G17 | S18: =+P18+Q18+R18
C19: =+'SITUACION COMERCIAL'!AB21 | G19: =+G18+1 | H19: 1 | I19: 1 | J19: E | K19: 2 | L19: 48 | M19: . | N19: . | O19: . | P19: =+'SITUACION COMERCIAL'!S21 | Q19: =+MEJORAS!G18 | S19: =+P19+Q19+R19
C20: =+'SITUACION COMERCIAL'!AB22 | G20: =+G19+1 | H20: 1 | I20: 1 | J20: F | K20: 2 | L20: 14 | M20: 21 | N20: . | O20: . | P20: =+'SITUACION COMERCIAL'!S22 | Q20: =+MEJORAS!G19 | S20: =+P20+Q20+R20
C21: =+'SITUACION COMERCIAL'!AB23 | G21: =+G20+1 | H21: 1 | I21: 2 | J21: A | K21: 4 | L21: 60 | M21: 54 | N21: . | O21: . | P21: =+'SITUACION COMERCIAL'!S23 | Q21: =+MEJORAS!G20 | R21: 4300 | S21: =+P21+Q21+R21
C22: =+'SITUACION COMERCIAL'!AB24 | G22: =+G21+1 | H22: 1 | I22: 2 | J22: B | K22: 3 | L22: 13 | M22: 20 | N22: . | O22: . | P22: =+'SITUACION COMERCIAL'!S24 | Q22: =+MEJORAS!G21 | R22: 3990 | S22: =+P22+Q22+R22
C23: =+'SITUACION COMERCIAL'!AB25 | G23: =+G22+1 | H23: 1 | I23: 2 | J23: C | K23: 2 | L23: 44 | M23: 43 | N23: . | O23: . | P23: =+'SITUACION COMERCIAL'!S25 | Q23: =+MEJORAS!G22 | R23: 2850 | S23: =+P23+Q23+R23
C24: =+'SITUACION COMERCIAL'!AB26 | G24: =+G23+1 | H24: 1 | I24: 2 | J24: D | K24: 2 | L24: 15 | M24: 22 | N24: . | O24: . | P24: =+'SITUACION COMERCIAL'!S26 | Q24: =+MEJORAS!G23 | S24: =+P24+Q24+R24
C25: =+'SITUACION COMERCIAL'!AB27 | G25: =+G24+1 | H25: 1 | I25: 2 | J25: E | K25: 2 | L25: 58 | M25: 51 | P25: =+'SITUACION COMERCIAL'!S27 | Q25: =+MEJORAS!G24 | S25: =+P25+Q25+R25
C26: =+'SITUACION COMERCIAL'!#REF! | G26: =+G25+1 | H26: 1 | I26: 2 | J26: F | K26: 2 | L26: 42 | M26: 42 | N26: . | O26: . | P26: =+'SITUACION COMERCIAL'!S28 | Q26: =+MEJORAS!G25 | S26: =+P26+Q26+R26
C27: =+'SITUACION COMERCIAL'!AB29 | G27: =+G26+1 | H27: 1 | I27: 3 | J27: A | K27: 4 | L27: 59 | M27: 53 | N27: 50 | O27: . | P27: =+'SITUACION COMERCIAL'!S29 | Q27: =+MEJORAS!G26 | S27: =+P27+Q27+R27
C28: =+'SITUACION COMERCIAL'!AB30 | G28: =+G27+1 | H28: 1 | I28: 3 | J28: B | K28: 3 | L28: 16 | M28: 23 | N28: . | O28: . | P28: =+'SITUACION COMERCIAL'!S30 | Q28: =+MEJORAS!G27 | S28: =+P28+Q28+R28
C29: =+'SITUACION COMERCIAL'!AB31 | G29: =+G28+1 | H29: 1 | I29: 3 | J29: C | K29: 2 | L29: 38 | M29: 25 | N29: . | O29: . | P29: =+'SITUACION COMERCIAL'!S31 | Q29: =+MEJORAS!G28 | S29: =+P29+Q29+R29
C30: =+'SITUACION COMERCIAL'!AB32 | G30: =+G29+1 | H30: 1 | I30: 3 | J30: D | K30: 2 | L30: 45 | M30: 44 | N30: . | O30: . | P30: =+'SITUACION COMERCIAL'!S32 | Q30: =+MEJORAS!G29 | S30: =+P30+Q30+R30
C31: =+'SITUACION COMERCIAL'!AB33 | G31: =+G30+1 | H31: 1 | I31: 3 | J31: E | K31: 2 | L31: 11 | M31: 15 | N31: . | O31: . | P31: =+'SITUACION COMERCIAL'!S33 | Q31: =+MEJORAS!G30 | S31: =+P31+Q31+R31
C32: =+'SITUACION COMERCIAL'!AB34 | G32: =+G31+1 | H32: 1 | I32: 3 | J32: F | K32: 2 | L32: 51 | M32: 46 | N32: . | O32: . | P32: =+'SITUACION COMERCIAL'!S34 | Q32: =+MEJORAS!G31 | S32: =+P32+Q32+R32
C33: =+'SITUACION COMERCIAL'!AB35 | G33: =+G32+1 | H33: 1 | I33: 4 | J33: A | K33: 4 | L33: 41 | M33: 52 | N33: . | O33: . | P33: =+'SITUACION COMERCIAL'!S35 | Q33: =+MEJORAS!G32 | S33: =+P33+Q33+R33
C34: =+'SITUACION COMERCIAL'!AB36 | G34: =+G33+1 | H34: 1 | I34: 4 | J34: B | K34: 2 | L34: 8 | M34: 12 | N34: . | O34: . | P34: =+'SITUACION COMERCIAL'!S36 | Q34: =+MEJORAS!G33 | S34: =+P34+Q34+R34
C35: =+'SITUACION COMERCIAL'!AB37 | G35: =+G34+1 | H35: 1 | I35: 4 | J35: C | K35: 2 | L35: 65 | M35: 59 | N35: . | O35: . | P35: =+'SITUACION COMERCIAL'!S37 | Q35: =+MEJORAS!G34 | S35: =+P35+Q35+R35
C36: =+'SITUACION COMERCIAL'!AB38 | G36: =+G35+1 | H36: 1 | I36: 4 | J36: D | K36: 2 | L36: 53 | M36: 19 | N36: . | O36: . | P36: =+'SITUACION COMERCIAL'!S38 | Q36: =+MEJORAS!G35 | S36: =+P36+Q36+R36
C37: =+'SITUACION COMERCIAL'!AB39 | G37: =+G36+1 | H37: 1 | I37: 5 | J37: A | K37: 4 | L37: 52 | M37: 47 | N37: 49 | O37: . | P37: 267700 | Q37: =+MEJORAS!G36 | S37: =+P37+Q37+R37
C38: =+'SITUACION COMERCIAL'!AB40 | G38: =+G37+1 | H38: 1 | I38: 5 | J38: B | K38: 4 | L38: 6 | M38: 10 | N38: . | O38: . | P38: =+'SITUACION COMERCIAL'!S40 | Q38: =+MEJORAS!G37 | S38: =+P38+Q38+R38
C39: =+'SITUACION COMERCIAL'!AB41 | G39: =+G38+1 | H39: 1 | I39: 5 | J39: C | K39: 4 | L39: 46 | M39: 45 | N39: . | O39: . | P39: =+'SITUACION COMERCIAL'!S41 | Q39: =+MEJORAS!G38 | S39: =+P39+Q39+R39
C40: =+'SITUACION COMERCIAL'!AB42 | G40: =+G39+1 | H40: 2 | I40: BAJA | J40: A | K40: 5 | L40: 22 | M40: 30 | N40: . | O40: . | P40: =+'SITUACION COMERCIAL'!S42 | Q40: =+MEJORAS!G39 | S40: =+P40+Q40+R40
C41: =+'SITUACION COMERCIAL'!AB43 | G41: =+G40+1 | H41: 2 | I41: BAJA | J41: B | K41: 4 | L41: 21 | M41: 29 | N41: . | O41: . | P41: =+'SITUACION COMERCIAL'!S43 | Q41: =+MEJORAS!G40 | S41: =+P41+Q41+R41
C42: =+'SITUACION COMERCIAL'!AB44 | G42: =+G41+1 | H42: 2 | I42: BAJA | J42: C | K42: 3 | L42: 33 | M42: 5 | N42: . | O42: . | P42: =+'SITUACION COMERCIAL'!S44 | Q42: =+MEJORAS!G41 | S42: =+P42+Q42+R42
C43: =+'SITUACION COMERCIAL'!AB45 | G43: =+G42+1 | H43: 2 | I43: BAJA | J43: D | K43: 2 | L43: 20 | M43: 28 | N43: . | O43: . | P43: =+'SITUACION COMERCIAL'!S45 | Q43: =+MEJORAS!G42 | S43: =+P43+Q43+R43
C44: =+'SITUACION COMERCIAL'!AB46 | G44: =+G43+1 | H44: 2 | I44: BAJA | J44: E | K44: 3 | L44: 19 | M44: 27 | N44: . | O44: . | P44: =+'SITUACION COMERCIAL'!S46 | Q44: =+MEJORAS!G43 | S44: =+P44+Q44+R44
C45: =+'SITUACION COMERCIAL'!AB47 | G45: =+G44+1 | H45: 2 | I45: 1 | J45: A | K45: 5 | L45: 61 | M45: 55 | N45: 39 | O45: . | P45: =+'SITUACION COMERCIAL'!S47 | Q45: =+MEJORAS!G44 | R45: 5750 | S45: =+P45+Q45+R45
...

Sheet FACTURACION
F1: =+F5+F13+F35+F36+F38+F56 | G1: =+F1*0.25
E3: TITULAR ACTUAL | F3: Precio base con actualizacion | G3: Origen | H3: Honorarios totales | K3: Liquidacion 1 | L3: liquidación 2 | M3: liq. 31/05/2024 | N3: liquidación agosto | O3: Liquidacion 2/09/24 | P3: lLiquidación 10/2024 | Q3: 45890 | R3: 45930 | S3: 46010 | U3: FACTURADO | V3: pte FACTURAR | W3: PTE A ENTREGA
H4: Importe | I4: % | J4: devengados | K4: 25% h. totales | L4: 50% h. totales-liquidación1 | M4: 50% honorarios totales | N4: 50% honorarios totales | O4: 50% honorarios totales | P4: 50% honorarios totales | Q4: 50% honorarios totales | R4: 50% honorarios totales | S4: 50% honorarios totales
A5: 1 | B5: 1 | C5: BAJA | D5: A | E5: =+'SITUACION COMERCIAL'!AB12 | F5: =IF('SITUACION COMERCIAL'!A12="RESERVADO",'SITUACION COMERCIAL'!S12,0) | G5: HABITAT | H5: =IF(G5="HABITAT",F5*0.025,F5*0.02) | I5: =+H5/F5 | J5: =IF('SITUACION COMERCIAL'!A12="RESERVADO",H5/2,0) | K5: 0 | L5: 3875 | Q5: -3875 | U5: =SUM(K5:T5) | V5: =+J5-K5-L5-M5-N5-O5-P5-T5-Q5-R5-S5 | W5: =+H5-U5 | X5: AARON ALEJANDRO VALVERDE VILLALON
A6: =+A5+1 | B6: 1 | C6: BAJA | D6: B | E6: =+'SITUACION COMERCIAL'!AB13 | F6: =IF('SITUACION COMERCIAL'!A13="RESERVADO",'SITUACION COMERCIAL'!S13,0) | G6: HABITAT | H6: =IF(G6="HABITAT",F6*0.025,F6*0.02) | I6: =+H6/F6 | J6: =IF('SITUACION COMERCIAL'!A13="RESERVADO",H6/2,0) | K6: 1468.125 | L6: 1468.125 | U6: =SUM(K6:T6) | V6: =+J6-K6-L6-M6-N6-O6-P6-T6-Q6-R6-S6 | W6: =+H6-U6 | X6: MANUEL PEÑA GRAGERA
A7: 3 | B7: 1 | C7: BAJA | D7: C | E7: =+'SITUACION COMERCIAL'!AB14 | F7: =IF('SITUACION COMERCIAL'!A14="RESERVADO",'SITUACION COMERCIAL'!S14,0) | G7: HABITAT | H7: =IF(G7="HABITAT",F7*0.025,F7*0.02) | I7: =+H7/F7 | J7: =IF('SITUACION COMERCIAL'!A14="RESERVADO",H7/2,0) | L7: 0 | O7: 1912.5 | U7: =SUM(K7:T7) | V7: =+J7-K7-L7-M7-N7-O7-P7-T7-Q7-R7-S7 | W7: =+H7-U7
A8: =+A7+1 | B8: 1 | C8: BAJA | D8: D | E8: =+'SITUACION COMERCIAL'!AB15 | F8: =IF('SITUACION COMERCIAL'!A15="RESERVADO",'SITUACION COMERCIAL'!S15,0) | G8: HABITAT | H8: =IF(G8="HABITAT",F8*0.025,F8*0.02) | I8: =+H8/F8 | J8: =IF('SITUACION COMERCIAL'!A15="RESERVADO",H8/2,0) | K8: 0 | L8: 2225 | U8: =SUM(K8:T8) | V8: =+J8-K8-L8-M8-N8-O8-P8-T8-Q8-R8-S8 | W8: =+H8-U8 | X8: ISIDORA ROMERO MARTIN
A9: =+A8+1 | B9: 1 | C9: BAJA | D9: E | E9: =+'SITUACION COMERCIAL'!AB16 | F9: =IF('SITUACION COMERCIAL'!A16="RESERVADO",'SITUACION COMERCIAL'!S16,0) | G9: HABITAT | H9: =IF(G9="HABITAT",F9*0.025,F9*0.02) | I9: =+H9/F9 | J9: =IF('SITUACION COMERCIAL'!A16="RESERVADO",H9/2,0) | Q9: 2687.5 | U9: =SUM(K9:T9) | V9: =+J9-K9-L9-M9-N9-O9-P9-T9-Q9-R9-S9 | W9: =+H9-U9
A10: =+A9+1 | B10: 1 | C10: 1 | D10: A | E10: =+'SITUACION COMERCIAL'!AB17 | F10: =IF('SITUACION COMERCIAL'!A17="RESERVADO",'SITUACION COMERCIAL'!S17,0) | G10: HABITAT | H10: =IF(G10="HABITAT",F10*0.025,F10*0.02) | I10: =+H10/F10 | J10: =IF('SITUACION COMERCIAL'!A17="RESERVADO",H10/2,0) | K10: 0 | L10: 3792.5 | U10: =SUM(K10:T10) | V10: =+J10-K10-L10-M10-N10-O10-P10-T10-Q10-R10-S10 | W10: =+H10-U10 | X10: JOSE MARIA PRUDENCIO ALONSO
A11: =+A10+1 | B11: 1 | C11: 1 | D11: B | E11: =+'SITUACION COMERCIAL'!AB18 | F11: =IF('SITUACION COMERCIAL'!A18="RESERVADO",'SITUACION COMERCIAL'!S18,0) | G11: HABITAT | H11: =IF(G11="HABITAT",F11*0.025,F11*0.02) | I11: =+H11/F11 | J11: =IF('SITUACION COMERCIAL'!A18="RESERVADO",H11/2,0) | R11: 3275 | U11: =SUM(K11:T11) | V11: =+J11-K11-L11-M11-N11-O11-P11-T11-Q11-R11-S11 | W11: =+H11-U11
A12: =+A11+1 | B12: 1 | C12: 1 | D12: C | E12: =+'SITUACION COMERCIAL'!AB19 | F12: =IF('SITUACION COMERCIAL'!A19="RESERVADO",'SITUACION COMERCIAL'!S19,0) | G12: HABITAT | H12: =IF(G12="HABITAT",F12*0.025,F12*0.02) | I12: =+H12/F12 | J12: =IF('SITUACION COMERCIAL'!A19="RESERVADO",H12/2,0) | K12: 1105 | L12: 1067.725 | U12: =SUM(K12:T12) | V12: =+J12-K12-L12-M12-N12-O12-P12-T12-Q12-R12-S12 | W12: =+H12-U12 | X12: AMALIA CABANILLAS BAENA
A13: =+A12+1 | B13: 1 | C13: 1 | D13: D | E13: =+'SITUACION COMERCIAL'!AB20 | F13: =IF('SITUACION COMERCIAL'!A20="RESERVADO",'SITUACION COMERCIAL'!S20,0) | G13: HABITAT | H13: =IF(G13="HABITAT",F13*0.025,F13*0.02) | I13: =+H13/F13 | J13: =IF('SITUACION COMERCIAL'!A20="RESERVADO",H13/2,0) | S13: 2612.5 | U13: =SUM(K13:T13)-K13 | V13: =+J13-K13-L13-M13-N13-O13-P13-T13-Q13-R13-S13 | W13: =+H13-U13
A14: =+A13+1 | B14: 1 | C14: 1 | D14: E | E14: =+'SITUACION COMERCIAL'!AB21 | F14: =IF('SITUACION COMERCIAL'!A21="RESERVADO",'SITUACION COMERCIAL'!S21,0) | G14: HABITAT | H14: =IF(G14="HABITAT",F14*0.025,F14*0.02) | I14: =+H14/F14 | J14: =IF('SITUACION COMERCIAL'!A21="RESERVADO",H14/2,0) | K14: 0 | L14: 2225 | U14: =SUM(K14:T14) | V14: =+J14-K14-L14-M14-N14-O14-P14-T14-Q14-R14-S14 | W14: =+H14-U14 | X14: VICTOR JOSE ROJAS MORENO
A15: =+A14+1 | B15: 1 | C15: 1 | D15: F | E15: =+'SITUACION COMERCIAL'!AB22 | F15: =IF('SITUACION COMERCIAL'!A22="RESERVADO",'SITUACION COMERCIAL'!S22,0) | G15: HABITAT | H15: =IF(G15="HABITAT",F15*0.025,F15*0.02) | I15: =+H15/F15 | J15: =IF('SITUACION COMERCIAL'!A22="RESERVADO",H15/2,0) | N15: 2312.5 | U15: =SUM(K15:T15) | V15: =+J15-K15-L15-M15-N15-O15-P15-T15-Q15-R15-S15 | W15: =+H15-U15 | X15: JUAN MANUEL DURAN GUERRERO
A16: =+A15+1 | B16: 1 | C16: 2 | D16: A | E16: =+'SITUACION COMERCIAL'!AB23 | F16: =IF('SITUACION COMERCIAL'!A23="RESERVADO",'SITUACION COMERCIAL'!S23,0) | G16: EDETICA | H16: =IF(G16="HABITAT",F16*0.025,F16*0.02) | I16: =+H16/F16 | J16: =IF('SITUACION COMERCIAL'!A23="RESERVADO",H16/2,0) | K16: 1399.5 | L16: 1399.5 | U16: =SUM(K16:T16) | V16: =+J16-K16-L16-M16-N16-O16-P16-T16-Q16-R16-S16 | W16: =+H16-U16 | X16: IGNACIO AMARO BLANCO
A17: =+A16+1 | B17: 1 | C17: 2 | D17: B | E17: =+'SITUACION COMERCIAL'!AB24 | F17: =IF('SITUACION COMERCIAL'!A24="RESERVADO",'SITUACION COMERCIAL'!S24,0) | G17: HABITAT | H17: =IF(G17="HABITAT",F17*0.025,F17*0.02) | I17: =+H17/F17 | J17: =IF('SITUACION COMERCIAL'!A24="RESERVADO",H17/2,0) | K17: 1491.25 | L17: 1491.25 | U17: =SUM(K17:T17) | V17: =+J17-K17-L17-M17-N17-O17-P17-T17-Q17-R17-S17 | W17: =+H17-U17 | X17: SATURNINO GONZALEZ -HABA GIL
A18: =+A17+1 | B18: 1 | C18: 2 | D18: C | E18: =+'SITUACION COMERCIAL'!AB25 | F18: =IF('SITUACION COMERCIAL'!A25="RESERVADO",'SITUACION COMERCIAL'!S25,0) | G18: HABITAT | H18: =IF(G18="HABITAT",F18*0.025,F18*0.02) | I18: =+H18/F18 | J18: =IF('SITUACION COMERCIAL'!A25="RESERVADO",H18/2,0) | K18: 1118.125 | L18: 1118.125 | U18: =SUM(K18:T18) | V18: =+J18-K18-L18-M18-N18-O18-P18-T18-Q18-R18-S18 | W18: =+H18-U18 | X18: JUAN FRANCISCO OTERO MARTIN
A19: =+A18+1 | B19: 1 | C19: 2 | D19: D | E19: =+'SITUACION COMERCIAL'!AB26 | F19: =IF('SITUACION COMERCIAL'!A26="RESERVADO",'SITUACION COMERCIAL'!S26,0) | G19: HABITAT | H19: =IF(G19="HABITAT",F19*0.025,F19*0.02) | I19: =+H19/F19 | J19: =IF('SITUACION COMERCIAL'!A26="RESERVADO",H19/2,0) | M19: 2312.5 | U19: =SUM(K19:T19)-K19 | V19: =+J19-K19-L19-M19-N19-O19-P19-T19-Q19-R19-S19 | W19: =+H19-U19 | X19: MARIA JESUS FERNANDEZ SANCHEZ
A20: =+A19+1 | B20: 1 | C20: 2 | D20: E | E20: =+'SITUACION COMERCIAL'!AB27 | F20: =IF('SITUACION COMERCIAL'!A27="RESERVADO",'SITUACION COMERCIAL'!S27,0) | G20: HABITAT | H20: =IF(G20="HABITAT",F20*0.025,F20*0.02) | I20: =+H20/F20 | J20: =IF('SITUACION COMERCIAL'!A27="RESERVADO",H20/2,0) | K20: 1087.5 | L20: 1175 | U20: =SUM(K20:T20) | V20: =+J20-K20-L20-M20-N20-O20-P20-T20-Q20-R20-S20 | W20: =+H20-U20 | X20: MANUEL JOSE SUAREZ MARTIN
A21: =+A20+1 | B21: 1 | C21: 2 | D21: F | E21: =+'SITUACION COMERCIAL'!AB28 | F21: =IF('SITUACION COMERCIAL'!A28="RESERVADO",'SITUACION COMERCIAL'!S28,0) | G21: HABITAT | H21: =IF(G21="HABITAT",F21*0.025,F21*0.02) | I21: =+H21/F21 | J21: =IF('SITUACION COMERCIAL'!A28="RESERVADO",H21/2,0) | N21: 2337.5 | U21: =SUM(K21:T21)-K21 | V21: =+J21-K21-L21-M21-N21-O21-P21-T21-Q21-R21-S21 | W21: =+H21-U21
A22: =+A21+1 | B22: 1 | C22: 3 | D22: A | E22: =+'SITUACION COMERCIAL'!AB29 | F22: =IF('SITUACION COMERCIAL'!A29="RESERVADO",'SITUACION COMERCIAL'!S29,0) | G22: HABITAT | H22: =IF(G22="HABITAT",F22*0.025,F22*0.02) | I22: =+H22/F22 | J22: =IF('SITUACION COMERCIAL'!A29="RESERVADO",H22/2,0) | K22: 1875.625 | L22: 1875.625 | U22: =SUM(K22:T22) | V22: =+J22-K22-L22-M22-N22-O22-P22-T22-Q22-R22-S22 | W22: =+H22-U22 | X22: DIEGO GARCIA RUBIO
A23: =+A22+1 | B23: 1 | C23: 3 | D23: B | E23: =+'SITUACION COMERCIAL'!AB30 | F23: =IF('SITUACION COMERCIAL'!A30="RESERVADO",'SITUACION COMERCIAL'!S30,0) | G23: HABITAT | H23: =IF(G23="HABITAT",F23*0.025,F23*0.02) | I23: =+H23/F23 | J23: =IF('SITUACION COMERCIAL'!A30="RESERVADO",H23/2,0) | K23: 1498.125 | L23: 1498.125 | U23: =SUM(K23:T23) | V23: =+J23-K23-L23-M23-N23-O23-P23-T23-Q23-R23-S23 | W23: =+H23-U23 | X23: FELIPA PEREZ CORRALES
A24: =+A23+1 | B24: 1 | C24: 3 | D24: C | E24: =+'SITUACION COMERCIAL'!AB31 | F24: =IF('SITUACION COMERCIAL'!A31="RESERVADO",'SITUACION COMERCIAL'!S31,0) | G24: HABITAT | H24: =IF(G24="HABITAT",F24*0.025,F24*0.02) | I24: =+H24/F24 | J24: =IF('SITUACION COMERCIAL'!A31="RESERVADO",H24/2,0) | K24: 1135 | L24: 1135 | U24: =SUM(K24:T24) | V24: =+J24-K24-L24-M24-N24-O24-P24-T24-Q24-R24-S24 | W24: =+H24-U24 | X24: PAULINO CONEJO NAVARRETE
A25: =+A24+1 | B25: 1 | C25: 3 | D25: D | E25: =+'SITUACION COMERCIAL'!AB32 | F25: =IF('SITUACION COMERCIAL'!A32="RESERVADO",'SITUACION COMERCIAL'!S32,0) | G25: HABITAT | H25: =IF(G25="HABITAT",F25*0.025,F25*0.02) | I25: =+H25/F25 | J25: =IF('SITUACION COMERCIAL'!A32="RESERVADO",H25/2,0) | K25: 1150 | L25: 1150 | U25: =SUM(K25:T25) | V25: =+J25-K25-L25-M25-N25-O25-P25-T25-Q25-R25-S25 | W25: =+H25-U25 | X25: PAULINO CONEJO NAVARRETE
A26: =+A25+1 | B26: 1 | C26: 3 | D26: E | E26: =+'SITUACION COMERCIAL'!AB33 | F26: =IF('SITUACION COMERCIAL'!A33="RESERVADO",'SITUACION COMERCIAL'!S33,0) | G26: HABITAT | H26: =IF(G26="HABITAT",F26*0.025,F26*0.02) | I26: =+H26/F26 | J26: =IF('SITUACION COMERCIAL'!A33="RESERVADO",H26/2,0) | K26: 1150 | L26: 1150 | U26: =SUM(K26:T26) | V26: =+J26-K26-L26-M26-N26-O26-P26-T26-Q26-R26-S26 | W26: =+H26-U26 | X26: TRINIDAD VILLALOBOS SAAVEDRA
A27: =+A26+1 | B27: 1 | C27: 3 | D27: F | E27: =+'SITUACION COMERCIAL'!AB34 | F27: =IF('SITUACION COMERCIAL'!A34="RESERVADO",'SITUACION COMERCIAL'!S34,0) | G27: HABITAT | H27: =IF(G27="HABITAT",F27*0.025,F27*0.02) | I27: =+H27/F27 | J27: =IF('SITUACION COMERCIAL'!A34="RESERVADO",H27/2,0) | K27: 1106.25 | L27: 1193.75 | U27: =SUM(K27:T27) | V27: =+J27-K27-L27-M27-N27-O27-P27-T27-Q27-R27-S27 | W27: =+H27-U27 | X27: MARIA JOSEFA MANCHADO MORAGA
A28: =+A27+1 | B28: 1 | C28: 4 | D28: A | E28: =+'SITUACION COMERCIAL'!AB35 | F28: =IF('SITUACION COMERCIAL'!A35="RESERVADO",'SITUACION COMERCIAL'!S35,0) | G28: EDETICA | H28: =IF(G28="HABITAT",F28*0.025,F28*0.02) | I28: =+H28/F28 | J28: =IF('SITUACION COMERCIAL'!A35="RESERVADO",H28/2,0) | K28: 1383 | L28: 1383 | U28: =SUM(K28:T28) | V28: =+J28-K28-L28-M28-N28-O28-P28-T28-Q28-R28-S28 | W28: =+H28-U28 | X28: SERVILIANO VALENCIA DIAZ
A29: =+A28+1 | B29: 1 | C29: 4 | D29: B | E29: =+'SITUACION COMERCIAL'!AB36 | F29: =IF('SITUACION COMERCIAL'!A36="RESERVADO",'SITUACION COMERCIAL'!S36,0) | G29: HABITAT | H29: =IF(G29="HABITAT",F29*0.025,F29*0.02) | I29: =+H29/F29 | J29: =IF('SITUACION COMERCIAL'!A36="RESERVADO",H29/2,0) | K29: 0 | L29: 2373.75 | U29: =SUM(K29:T29) | V29: =+J29-K29-L29-M29-N29-O29-P29-T29-Q29-R29-S29 | W29: =+H29-U29 | X29: ANTONIO SANTIAGO ROMERO
A30: =+A29+1 | B30: 1 | C30: 4 | D30: C | E30: =+'SITUACION COMERCIAL'!AB37 | F30: =IF('SITUACION COMERCIAL'!A37="RESERVADO",'SITUACION COMERCIAL'!S37,0) | G30: HABITAT | H30: =IF(G30="HABITAT",F30*0.025,F30*0.02) | I30: =+H30/F30 | J30: =IF('SITUACION COMERCIAL'!A37="RESERVADO",H30/2,0) | K30: 0 | L30: 2337.5 | U30: =SUM(K30:T30) | V30: =+J30-K30-L30-M30-N30-O30-P30-T30-Q30-R30-S30 | W30: =+H30-U30 | X30: VICENTE MIGUEL SUAREZ MARTIN
A31: =+A30+1 | B31: 1 | C31: 4 | D31: D | E31: =+'SITUACION COMERCIAL'!AB38 | F31: =IF('SITUACION COMERCIAL'!A38="RESERVADO",'SITUACION COMERCIAL'!S38,0) | G31: HABITAT | H31: =IF(G31="HABITAT",F31*0.025,F31*0.02) | I31: =+H31/F31 | J31: =IF('SITUACION COMERCIAL'!A38="RESERVADO",H31/2,0) | K31: 0 | L31: 2373.75 | U31: =SUM(K31:T31) | V31: =+J31-K31-L31-M31-N31-O31-P31-T31-Q31-R31-S31 | W31: =+H31-U31 | X31: ELENA SANCHEZ RICO
A32: =+A31+1 | B32: 1 | C32: 5 | D32: A | E32: =+'SITUACION COMERCIAL'!AB39 | F32: =IF('SITUACION COMERCIAL'!A39="RESERVADO",'SITUACION COMERCIAL'!S39,0) | G32: EDETICA | H32: =IF(G32="HABITAT",F32*0.025,F32*0.02) | I32: =+H32/F32 | J32: =IF('SITUACION COMERCIAL'!A39="RESERVADO",H32/2,0) | K32: 1338.5 | L32: 1338.5 | U32: =SUM(K32:T32) | V32: 0 | W32: =+H32-U32 | X32: COMERCIAL ROMERO DE SONDEOS S.L.
A33: =+A32+1 | B33: 1 | C33: 5 | D33: B | E33: =+'SITUACION COMERCIAL'!AB40 | F33: =IF('SITUACION COMERCIAL'!A40="RESERVADO",'SITUACION COMERCIAL'!S40,0) | G33: HABITAT | H33: =IF(G33="HABITAT",F33*0.025,F33*0.02) | I33: =+H33/F33 | J33: =IF('SITUACION COMERCIAL'!A40="RESERVADO",H33/2,0) | R33: 3812.5 | U33: =SUM(K33:T33) | V33: =+J33-K33-L33-M33-N33-O33-P33-T33-Q33-R33-S33 | W33: =+H33-U33
A34: =+A33+1 | B34: 1 | C34: 5 | D34: C | E34: =+'SITUACION COMERCIAL'!AB41 | F34: =IF('SITUACION COMERCIAL'!A41="RESERVADO",'SITUACION COMERCIAL'!S41,0) | G34: HABITAT | H34: =IF(G34="HABITAT",F34*0.025,F34*0.02) | I34: =+H34/F34 | J34: =IF('SITUACION COMERCIAL'!A41="RESERVADO",H34/2,0) | K34: 1696.25 | L34: 1696.25 | U34: =SUM(K34:T34) | V34: =+J34-K34-L34-M34-N34-O34-P34-T34-Q34-R34-S34 | W34: =+H34-U34 | X34: ANGEL GUTIERREZ ROBLES
A35: =+A34+1 | B35: 2 | C35: BAJA | D35: A | E35: =+'SITUACION COMERCIAL'!AB42 | F35: =IF('SITUACION COMERCIAL'!A42="RESERVADO",'SITUACION COMERCIAL'!S42,0) | G35: HABITAT | H35: =IF(G35="HABITAT",F35*0.025,F35*0.02) | I35: =+H35/F35 | J35: =IF('SITUACION COMERCIAL'!A42="RESERVADO",H35/2,0) | S35: 4750 | U35: =SUM(K35:T35) | V35: =+J35-K35-L35-M35-N35-O35-P35-T35-Q35-R35-S35 | W35: =+H35-U35
A36: =+A35+1 | B36: 2 | C36: BAJA | D36: B | E36: =+'SITUACION COMERCIAL'!AB43 | F36: =IF('SITUACION COMERCIAL'!A43="RESERVADO",'SITUACION COMERCIAL'!S43,0) | G36: HABITAT | H36: =IF(G36="HABITAT",F36*0.025,F36*0.02) | I36: =+H36/F36 | J36: =IF('SITUACION COMERCIAL'!A43="RESERVADO",H36/2,0) | U36: =SUM(K36:T36) | V36: =+J36-K36-L36-M36-N36-O36-P36-T36-Q36-R36-S36 | W36: =+H36-U36
A37: =+A36+1 | B37: 2 | C37: BAJA | D37: C | E37: =+'SITUACION COMERCIAL'!AB44 | F37: =IF('SITUACION COMERCIAL'!A44="RESERVADO",'SITUACION COMERCIAL'!S44,0) | G37: HABITAT | H37: =IF(G37="HABITAT",F37*0.025,F37*0.02) | I37: =+H37/F37 | J37: =IF('SITUACION COMERCIAL'!A44="RESERVADO",H37/2,0) | K37: 1535.625 | L37: 1535.625 | U37: =SUM(K37:T37) | V37: =+J37-K37-L37-M37-N37-O37-P37-T37-Q37-R37-S37 | W37: =+H37-U37 | X37: CLAUDIO BORREGO DOMÍNGUEZ
A38: =+A37+1 | B38: 2 | C38: BAJA | D38: D | E38: =+'SITUACION COMERCIAL'!AB45 | F38: =IF('SITUACION COMERCIAL'!A45="RESERVADO",'SITUACION COMERCIAL'!S45,0) | G38: HABITAT | H38: =IF(G38="HABITAT",F38*0.025,F38*0.02) | I38: =+H38/F38 | J38: =IF('SITUACION COMERCIAL'!A45="RESERVADO",H38/2,0) | U38: =SUM(K38:T38) | V38: =+J38-K38-L38-M38-N38-O38-P38-T38-Q38-R38-S38 | W38: =+H38-U38
A39: =+A38+1 | B39: 2 | C39: BAJA | D39: E | E39: =+'SITUACION COMERCIAL'!AB46 | F39: =IF('SITUACION COMERCIAL'!A46="RESERVADO",'SITUACION COMERCIAL'!S46,0) | G39: HABITAT | H39: =IF(G39="HABITAT",F39*0.025,F39*0.02) | I39: =+H39/F39 | J39: =IF('SITUACION COMERCIAL'!A46="RESERVADO",H39/2,0) | K39: 1523.125 | L39: 1785.625 | U39: =SUM(K39:T39) | V39: =+J39-K39-L39-M39-N39-O39-P39-T39-Q39-R39-S39 | W39: =+H39-U39 | X39: ANTONIO MURIEL VADILLO
A40: =+A39+1 | B40: 2 | C40: 1 | D40: A | E40: =+'SITUACION COMERCIAL'!AB47 | F40: =IF('SITUACION COMERCIAL'!A47="RESERVADO",'SITUACION COMERCIAL'!S47,0) | G40: HABITAT | H40: =IF(G40="HABITAT",F40*0.025,F40*0.02) | I40: =+H40/F40 | J40: =IF('SITUACION COMERCIAL'!A47="RESERVADO",H40/2,0) | K40: 0 | L40: 4700 | U40: =SUM(K40:T40) | V40: =+J40-K40-L40-M40-N40-O40-P40-T40-Q40-R40-S40 | W40: =+H40-U40 | X40: CARMEN VICTORIA ROJAS MORENO
A41: =+A40+1 | B41: 2 | C41: 1 | D41: B | E41: =+'SITUACION COMERCIAL'!AB48 | F41: =IF('SITUACION COMERCIAL'!A48="RESERVADO",'SITUACION COMERCIAL'!S48,0) | G41: HABITAT | H41: =IF(G41="HABITAT",F41*0.025,F41*0.02) | I41: =+H41/F41 | J41: =IF('SITUACION COMERCIAL'!A48="RESERVADO",H41/2,0) | K41: 1780.625 | L41: 1780.625 | U41: =SUM(K41:T41) | V41: =+J41-K41-L41-M41-N41-O41-P41-T41-Q41-R41-S41 | W41: =+H41-U41 | X41: JOSE MANUEL ROSON JIMENEZ
...
